Workbook

Sheet Talimatlar
A1: İbn Teymiyye Tutum Haritalama · H2 Manuel Doğrulama Atölyesi
A2: Bu çalışma İbn Teymiyye'nin Iman bahsindeki paralel pasajların (Mecmû V07 İbn Kāsım edisyonu ↔ Standalone Iman Albani edisyonu) manuel doğrulamasıdır.
A4: 📋 PROTOKOL
A5: 1. Aşağıdaki 'Etiketleme' sekmesine geçin.
A6: 2. Her satır bir pair (kaynak ↔ hedef pasaj). 26 pair var.
A7: 3. Sırayla her pair için:
A8: a. Sol kolonda 'Kaynak metin' (Mecmû V07 / İbn Kāsım edisyonu) okuyun.
A9: b. Sağ kolonda 'Hedef metin' (Standalone Iman / Albani edisyonu) okuyun.
A10: c. 'ETİKET' kolonuna tıklayın → açılır listeden 5 sınıftan birini seçin.
A11: d. 'Notlar' kolonuna kararınızın gerekçesini yazın (özellikle OVERLAP / NOISE için).
A12: 4. Excel her tuş vuruşunda otomatik kaydeder; özel bir 'kaydet' adımı gerekmiyor.
A13: 5. 'Özet' sekmesinde ilerlemeniz canlı güncellenir (kaç tamamlandı, sınıf dağılımı).
... A59: • Kararsız kaldığınız pair'leri 'Notlar' kolonunda 'TARTIŞMA' yazarak işaretleyin; atölye sonu birlikte tahkim edebiliriz.

Sheet Etiketleme
A1: # | B1: Bant | C1: Source ID | D1: Target ID | E1: Skor | F1: Adjusted | G1: QD-S | H1: QD-T | I1: Sayfalar | J1: Kaynak metin (Mecmû V07 / İbn Kāsım) | K1: Hedef metin (Standalone Iman / Albani) | L1: ETİKET | M1: Notlar
A2: 1 | B2: Çok yüksek (likely birebir) | C2: MF-V07-S09-P021 | D2: IMN-S00-P132 | E2: 0.958 | F2: 0.94 | G2: 0.02 | H2: 0.01 | I2: S: V07P328–V07P417 T: V01P007–V01P359 | J2: قلت: لفظ المجمل والمطلق والعام كان في اصطلاح الأئمة كالشافعي وأحمد وأبي عبيد وإسحاق وغيرهم سواء لا يريدون بالمجمل ما لا يفهم منه كما فسره به بعض المتأخرين وأخطأ في ذلك بل المجمل ما لا يكفي وحده في العمل به وإن كان ظاهره حقا كما في قوله تعالى {خذ من أموالهم صدقة تطهرهم وتزكيهم بها} فهذه الآية ظاهرها ومعناها مفهوم ليست مما لا يفهم المراد به؛ بل نفس ما دلت عليه لا يكفي وحده في العمل فإن المأمور به صدقة تكون مطهرة مزكية لهم هذا إنما يعرف ببيان الرسول صلى الله عليه وسلم ولهذا قال أحمد يحذر المتكلم في الفقه هذين " الأصلين ": المجمل والقياس. وقال: أكثر ما يخطئ الناس من جهة التأويل والقياس يريد بذلك ألا يحكم بما يدل عليه العام والمطلق قبل النظر فيما يخصه ويقيده ولا يعمل بالقياس قبل النظر في دلالة النصوص هل تدفعه فإن أكثر خطأ الناس تمسكهم بما يظنونه من دلالة اللفظ والقياس؛ فالأمور الظنية لا يعمل بها حتى يبحث عن المعارض بحثا يطمئن القلب إليه وإلا أخطأ من لم يفعل ذلك وهذا هو الواقع في المتمسكين بالظواهر والأقيسة ولهذا جعل الاحتجاج بالظواهر مع الإعراض عن تفسير النبي صلى الله عليه وسلم وأصحابه طريق أهل البدع. وله في ذلك مصنف كبير. وكذلك التمسك بالأقيسة مع الإعراض عن النصوص والآثار طريق أهل البدع. ولهذا كان كل قول ابتدعه هؤلاء قولا فاسدا وإنما الصواب من أقوالهم ما وافقوا فيه السلف من الصحابة والتابعين لهم بإحسان وقوله تعالى {يوصيكم الله في أولادكم} سماه عاما وهو مطلق في الأحوال يعمها على طريق البدل كما يعم قوله: {فتحرير رقبة} جميع الرقاب لا يعمها كما يعم لفظ الولد للأولاد. ومن أخذ بهذا لم يأخذ بما دل عليه ظاهر لفظ القرآن بل أخذ بما ظهر له مما سكت عنه القرآن فكان الظهور لسكوت القرآن عنه لا لدلالة القرآن على أنه ظاهر فكانوا متمسكين بظاهر من القول لا بظاهر القول؛ وعمدتهم عدم العلم بالنصوص التي فيها علم بما قيد وإلا فكل ما بينه القرآن وأظهره فهو حق؛ بخلاف ما يظهر للإنسان لمعنى آخر غير نفس القرآن يسمى ظاهر القرآن كاستدلالات أهل البدع من المرجئة والجهمية والخوارج والشيعة. قال أحمد: وأما من زعم أن الإيمان الإقرار فما يقول في المعرفة؟ هل يحتاج إلى المعرفة مع الإقرار؟ وهل يحتاج أن يكون مصدقا بما عرف؟ فإن زعم أنه يحتاج إلى المعرفة مع الإقرار فقد زعم أنه من شيئين وإن زعم أنه يحتاج أن يكون مقرا ومصدقا بما عرف فهو من ثلاثة أشياء؛ وإن جحد وقال: لا يحتاج إلى المعرفة والتصديق فقد قال قولا عظيما ولا أحسب أحدا يدفع المعرفة والتصديق وكذلك العمل مع هذه الأشياء. قلت أحمد وأبو ثور وغيرهما من الأئمة كانوا قد عرفوا أصل قول المرجئة وهو أن الإيمان لا يذهب بعضه ويبقى بعضه؛ فلا يكون إلا شيئا واحدا فلا يكون ذا عدد: اثنين أو ثلاثة فإنه إذا كان له عدد أمكن ذهاب بعضه وبقاء بعضه بل لا يكون إلا شيئا واحدا ولهذا قالت الجهمية: إنه شيء واحد في القلب. وقالت الكرامية: إنه شيء واحد على اللسان كل ذلك فرارا من تبعض الإيمان وتعدده فلهذا صاروا يناظرونهم بما يدل على أنه ليس شيئا واحدا كما قلتم. فأبو ثور احتج بما اجتمع عليه " الفقهاء المرجئة " من أنه تصديق وعمل ولم يكن بلغه قول متكلميهم وجهميتهم أو لم يعد خلافهم خلافا وأحمد ذكر أنه لا بد من المعرفة والتصديق مع الإقرار وقال: إن من جحد المعرفة والتصديق فقد قال قولا عظيما فإن فساد هذا القول معلوم من دين الإسلام ولهذا لم يذهب إليه أحد قبل الكرامية مع أن الكرامية لا تنكر وجوب المعرفة والتصديق ولكن تقول: لا يدخل في اسم الإيمان حذرا من تبعضه وتعدده لأنهم رأوا أنه لا يمكن أن يذهب بعضه ويبقى بعضه بل ذلك يقتضي أن يجتمع في القلب إيمان وكبر واعتقدوا الإجماع على نفي ذلك. كما ذكر هذا الإجماع الأشعري وغيره. وهذه الشبهة التي أوقعتهم مع علم كثير منهم وعبادته وحسن إسلامه وإيمانه ولهذا دخل في " إرجاء الفقهاء " جماعة هم عند الأمة أهل علم ودين. ولهذا لم يكفر أحد من السلف أحدا من " مرجئة الفقهاء " بل جعلوا هذا من بدع الأقوال والأفعال؛ لا من بدع العقائد فإن كثيرا من النزاع فيها لفظي لكن اللفظ المطابق للكتاب والسنة هو الصواب فليس لأحد أن يقول بخلاف قول الله ورسوله لا سيما وقد صار ذلك ذريعة إلى بدع أهل الكلام من أهل الإرجاء وغيرهم وإلى ظهور الفسق فصار ذلك الخطأ اليسير في اللفظ سببا لخطأ عظيم في العقائد والأعمال فلهذا عظم القول في ذم " الإرجاء " حتى قال إبراهيم النخعي: لفتنتهم - يعني المرجئة - أخوف على هذه الأمة من فتنة | K2: ليست مما لا يفهم المراد به، بل نفس ما دلت عليه لا يكفي وحده في العمل فإن المأمور به صدقة تكون مطهرة مزكية لهم، وهذا إنما يعرف ببيان الرسول صلى الله عليه وسلم؛ ولهذا قال أحمد يحذر المتكلم في الفقه هذين الأصلين: المجمل والقياس. وقال: أكثر ما يخطئ الناس من جهة التأويل والقياس، يريد بذلك ألا يحكم بما يدل عليه العام والمطلق قبل النظر فيما يخصه ويقيده، ولا يعمل بالقياس قبل النظر في دلالة النصوص هل تدفعه، فإن أكثر خطأ الناس تمسكهم بما يظنونه من دلالة اللفظ والقياس، فالأمور الظنية لا يعمل بها حتى يبحث عن المعارض بحثا يطمئن القلب إليه، وإلا أخطأ من لم يفعل ذلك. وهذا هو الواقع في المتمسكين بالظواهر والأقيسة؛ ولهذا جعل الاحتجاج بالظواهر مع الإعراض عن تفسير النبي صلى الله عليه وسلم وأصحابه طريق أهل البدع، وله في ذلك مصنف كبير. وكذلك التمسك بالأقيسة مع الإعراض عن النصوص والآثار طريق أهل البدع؛ ولهذا كان كل قول ابتدعه هؤلاء قولا فاسدا، وإنما الصواب من أقوالهم ما وافقوا فيه السلف من الصحابة والتابعين لهم بإحسان، وقوله تعالى: {يوصيكم الله في أولادكم} [النساء: 11] سماه عاما وهو مطلق في الأحوال، يعمها على طريق البدل، كما يعم قوله: {فتحرير رقبة} [المجادلة: 3] جميع الرقاب، لا يعمها كما يعم لفظ الولد للأولاد، ومن أخذ بهذا لم يأخذ بما دل عليه ظاهر لفظ القرآن، بل أخذ بما ظهر له مما سكت عنه القرآن، فكان الظهور لسكوت القرآن عنه، لا لدلالة القرآن على أنه ظاهر، فكانوا متمسكين بظاهر من القول لا بظاهر القول، وعمدتهم عدم العلم بالنصوص التي فيها علم بما قيد، وإلا فكل ما بينه القرآن وأظهره فهو حق، بخلاف ما يظهر للإنسان لمعنى آخر غير نفس القرآن يسمى ظاهر القرآن. كاستدلالات أهل البدع من المرجئة والجهمية والخوارج والشيعة. قال أحمد: وأما من زعم أن الإيمان الإقرار، فما يقول في المعرفة؟ هل يحتاج إلى المعرفة مع الإقرار؟ وهل يحتاج أن يكون مصدقا بما عرف؟ فإن زعم أنه يحتاج إلى المعرفة مع الإقرار فلقد زعم أنه من شيئين، وإن زعم أنه يحتاج أن يكون مقرا ومصدقا بما عرف فهو من ثلاثة أشياء، وإن جحد وقال: لا يحتاج إلى المعرفة والتصديق، فقد قال قولا عظيما، ولا أحسب أحدا يدفع المعرفة والتصديق وكذلك العمل مع هذه الأشياء. قلت: أحمد وأبو ثور وغيرهما من الأئمة كانوا قد عرفوا أصل قول المرجئة، وهو: أن الإيمان لا يذهب بعضه ويبقى بعضه، فلا يكون إلا شيئا واحدا فلا يكون ذا عدد؛ اثنين أو ثلاثة، فإنه إذا كان له عدد، أمكن ذهاب بعضه وبقاء بعضه، بل لا يكون إلا شيئا واحدا، ولهذا قالت الجهمية: إنه شيء واحد في القلب. وقالت الكرامية: إنه شيء واحد على اللسان، كل ذلك فرارا من تبعض الإيمان وتعدده، فلهذا صاروا يناظرونهم بما يدل على أنه ليس شيئا واحدا، كما قلتم، فأبو ثور احتج بما اجتمع عليه الفقهاء المرجئة، من أنه تصديق وعمل، ولم يكن بلغه قول متكلميهم وجهميتهم، أو لم يعد خلافهم خلافا، وأحمد ذكر أنه لابد من المعرفة والتصديق مع الإقرار، وقال: إن من جحد المعرفة والتصديق فقد قال قولا عظيما، فإن فساد هذا القول معلوم من دين الإسلام؛ ولهذا لم يذهب إليه أحد قبل الكرامية، مع أن الكرامية لا تنكر وجوب المعرفة والتصديق، ولكن تقول: لا يدخل في اسم الإيمان حذرا من تبعضه وتعدده؛ لأنهم رأوا أنه لا يمكن أن يذهب بعضه ويبقى بعضه، بل ذلك يقتضي أن يجتمع في القلب إيمان وكبر، واعتقدوا الإجماع على نفي ذلك، كما ذكر هذا الإجماع الأشعري وغيره. وهذه الشبهة التي أوقعتهم مع علم كثير منهم وعبادته وحسن إسلامه وإيمانه؛ ولهذا دخل في إرجاء الفقهاء جماعة هم عند الأمة أهل علم ودين؛ ولهذا لم يكفر أحد من السلف أحدا من مرجئة الفقهاء بل جعلوا هذا من بدع الأقوال والأفعال، لا من بدع العقائد، فإن كثيرا من النزاع فيها لفظي، لكن اللفظ المطابق للكتاب والسنة هو الصواب فليس لأحد أن يقول بخلاف قول الله ورسوله، لا سيما وقد صار ذلك ذريعة إلى بدع أهل الكلام من أهل الإرجاء وغيرهم وإلى ظهور الفسق، فصار ذلك الخطأ اليسير في اللفظ سببا لخطأ عظيم
A3: 2 | B3: Çok yüksek (likely birebir) | C3: MF-V07-S08-P005 | D3: IMN-S00-P105 | E3: 0.973 | F3: 0.915 | G3: 0.06 | H3: 0.06 | I3: S: V07P298–V07P327 T: V01P007–V01P359 | J3: فصل: ومما يسأل عنه أنه إذا كان ما أوجبه الله من الأعمال الظاهرة أكثر من هذه الخمس؛ فلماذا قال: الإسلام هذه الخمس وقد أجاب بعض الناس بأن هذه أظهر شعائر الإسلام وأعظمها وبقيام العبد بها يتم إسلامه وتركه لها يشعر بانحلال قيد انقياده. و " التحقيق " أن النبي صلى الله عليه وسلم ذكر الدين الذي هو استسلام العبد لربه مطلقا الذي يجب لله عبادة محضة على الأعيان. فيجب على كل من كان قادرا عليه ليعبد الله بها مخلصا له الدين. وهذه هي الخمس وما سوى ذلك فإنما يجب بأسباب لمصالح فلا يعم وجوبها جميع الناس؛ بل إما أن يكون فرضا على الكفاية كالجهاد والأمر بالمعروف والنهي عن المنكر؛ وما يتبع ذلك من إمارة وحكم وفتيا؛ وإقراء وتحديث وغير ذلك. وإما أن يجب بسبب حق للآدميين يختص به من وجب له وعليه وقد يسقط بإسقاطه. وإذا حصلت المصلحة أو الإبراء إما بإبرائه وإما بحصول المصلحة فحقوق العباد مثل قضاء الديون ورد الغصوب والعواري والودائع والإنصاف من المظالم من الدماء والأموال والأعراض؛ إنما هي حقوق الآدميين وإذا أبرئوا منها سقطت. وتجب على شخص دون شخص في حال دون حال لم تجب عبادة محضة لله على كل عبد قادر؛ ولهذا يشترك فيها المسلمون واليهود والنصارى بخلاف الخمسة فإنها من خصائص المسلمين. وكذلك ما يجب من صلة الأرحام وحقوق الزوجة والأولاد والجيران والشركاء والفقراء. وما يجب من أداء الشهادة والفتيا والقضاء والإمارة والأمر بالمعروف والنهي عن المنكر والجهاد؛ كل ذلك يجب بأسباب عارضة على بعض الناس دون بعض لجلب منافع ودفع مضار لو حصلت بدون فعل الإنسان لم تجب؛ فما كان مشتركا فهو واجب على الكفاية وما كان مختصا فإنما يجب على زيد دون عمرو لا يشترك الناس في وجوب عمل بعينه على كل أحد قادر سوى الخمس؛ فإن زوجة زيد وأقاربه ليست زوجة عمرو وأقاربه فليس الواجب على هذا مثل الواجب على هذا بخلاف صوم رمضان وحج البيت والصلوات الخمس والزكاة؛ فإن الزكاة وإن كانت حقا ماليا فإنها واجبة لله؛ والأصناف الثمانية مصارفها؛ ولهذا وجبت فيها النية ولم يجز أن يفعلها الغير عنه بلا إذنه ولم تطلب من الكفار. وحقوق العباد لا يشترط لها النية ولو أداها غيره عنه بغير إذنه برئت ذمته ويطالب بها الكفار وما يجب حقا لله تعالى كالكفارات هو بسبب من العبد وفيها شوب العقوبات فإن الواجب لله " ثلاثة أنواع ": عبادة محضة كالصلوات وعقوبات محضة كالحدود وما يشبهها كالكفارات. وكذلك كفارات الحج وما يجب بالنذر فإن ذلك يجب بسبب فعل من العبد وهو واجب في ذمته. وأما " الزكاة " فإنها تجب حقا لله في ماله. ولهذا يقال: ليس في المال حق سوى الزكاة أي ليس فيه حق يجب بسبب المال سوى الزكاة وإلا ففيه واجبات بغير سبب المال كما تجب النفقات للأقارب والزوجة والرقيق والبهائم ويجب حمل العاقلة ويجب قضاء الديون ويجب الإعطاء في النائبة ويجب إطعام الجائع وكسوة العاري فرضا على الكفاية؛ إلى غير ذلك من الواجبات المالية. لكن بسبب عارض والمال شرط وجوبها كالاستطاعة في الحج فإن البدن سبب الوجوب والاستطاعة شرط والمال في الزكاة هو السبب والوجوب معه؛ حتى لو لم يكن في بلده من يستحقها حملها إلى بلدة أخرى وهي حق وجب لله تعالى. ولهذا قال: من قال من الفقهاء: إن التكليف شرط فيها فلا تجب على الصغير والمجنون. وأما عامة الصحابة والجمهور كمالك والشافعي وأحمد فأوجبوها في مال الصغير والمجنون لأن مالهما من جنس مال غيرهما ووليهما يقوم مقامهما بخلاف بدنهما. فإنه إنما يتصرف بعقلهما؛ وعقلهما ناقص. وصار هذا كما يجب العشر في أرضهما مع أنه إنما يستحقه الثمانية. وكذلك إيجاب الكفارة في مالهما. والصلاة والصيام إنما تسقط لعجز العقل عن الإيجاب لا سيما إذا انضم إلى عجز البدن كالصغير. وهذا المعنى منتف في المال فإن الولي قام مقامهما في الفهم كما يقوم مقامهما في جميع ما يجب في المال وأما بدنهما فلا يجب عليهما فيه شيء. فصل: (*) قال محمد بن نصر: واستدلوا على أن الإيمان هو ما ذكروه بالآيات التي تلوناها عند ذكر تسمية الله الصلاة وسائر الطاعات إيمانا واستدلوا أيضا بما قص الله من إباء إبليس حين عصى ربه في سجدة واحدة (*) أمر أن يسجدها لآدم فأباها. فهل جحد إبليس ربه وهو يقول: {رب بما أغويتني} ويقول: {رب فأنظرني إلى يوم يبعثون} إيمانا منه بالبعث وإيمانا بنفاذ قدرته في إنظاره إياه إلى يوم يبعثون وهل جحد أحدا من أنبيائه أو أنكر شيئا من سلطانه وهو يحلف بعزته؟ وهل كان كفره إلا بترك سجدة واحدة أمر بها فأباها؟ قال: واستدلوا أيضا بما قص الله علينا من نبأ ابني آدم {إذ قربا قربانا فتقبل من أحدهما ولم يتقبل من الآخر} إلى قوله: {فأصبح من الخاسرين} قالوا: وهل جحد ربه؟ وكيف يجحده وهو يقرب القربان؟ . قالوا: قال الله تعالى: {إنما يؤمن بآياتنا الذين إذا ذكروا بها خروا سجدا وسبحوا بحمد ربهم وهم لا يستكبرون} ولم يقل: إذا ذكروا بها أقروا بها فقط. وقال: {الذين آتيناهم الكتاب يتلونه حق تلاوته أولئك يؤمنون به} يعني يتبعونه حق اتباعه Page | K3: والتحقيق أن النبي صلى الله عليه وسلم ذكر الدين الذي هو استسلام العبد لربه مطلقا، الذي يجب لله عبادة محضة على الأعيان. فيجب على كل من كان قادرا عليه ليعبد الله بها مخلصا له الدين. وهذه هي الخمس، وما سوى ذلك فإنما يجب بأسباب لمصالح، فلا يعم وجوبها جميع الناس، بل إما أن يكون فرضا على الكفاية، كالجهاد، والأمر بالمعروف، والنهي عن المنكر، وما يتبع ذلك من إمارة، وحكم، وفتيا، وإقراء، وتحديث، وغير ذلك. وإما أن يجب بسبب حق للآدميين يختص به من وجب له وعليه. وقد يسقط بإسقاطه، وإذا حصلت المصلحة أو الإبراء، إما بإبرائه وإما بحصول المصلحة، فحقوق العباد مثل قضاء الديون ورد الغصوب، والعواري والودائع، والإنصاف من المظالم من الدماء والأموال والأعراض، إنما هي حقوق الآدميين. وإذا أبرئوا منها سقطت. وتجب على شخص دون شخص في حال دون حال، لم تجب عبادة محضة لله على كل عبد قادر؛ ولهذا يشترك فيها المسلمون واليهود والنصارى، بخلاف الخمسة فإنها من خصائص المسلمين. وكذلك ما يجب من صلة الأرحام، وحقوق الزوجة، والأولاد والجيران والشركاء، والفقراء، وما يجب من أداء الشهادة، والفتيا، والقضاء، والإمارة، والأمر بالمعروف والنهي عن المنكر، والجهاد، كل ذلك يجب بأسباب عارضة على بعض الناس دون بعض لجلب منافع ودفع مضار، لو حصلت بدون فعل الإنسان لم تجب، فما كان مشتركا فهو واجب على الكفاية، وما كان مختصا فإنما يجب على زيد دون عمرو، لا يشترك الناس في وجوب عمل بعينه على كل أحد قادر سوى الخمس، فإن زوجة زيد وأقاربه ليست زوجة عمرو وأقاربه فليس الواجب على هذا مثل الواجب على هذا، بخلاف صوم رمضان، وحج البيت، والصلوات الخمس، والزكاة؛ فإن الزكاة وإن كانت حقا ماليا فإنها واجبة لله، والأصناف الثمانية مصارفها؛ ولهذا وجبت فيها النية، ولم يجز أن يفعلها الغير عنه بلا إذنه، ولم تطلب من الكفار. وحقوق العباد لا يشترط لها النية، ولو أداها غيره عنه بغير إذنه برئت ذمته، ويطالب بها الكفار، وما يجب حقا لله تعالى كالكفارات هو بسبب من العبد، وفيها شوب العقوبات، فإن الواجب لله ثلاثة أنواع: عبادة محضة كالصلوات، وعقوبات محضة كالحدود، وما يشبهها كالكفارات، وكذلك كفارات الحج، وما يجب بالنذر فإن ذلك يجب بسبب فعل من العبد، وهو واجب في ذمته. وأما الزكاة فإنها تجب حقا لله في ماله؛ ولهذا يقال: ليس في المال حق سوى الزكاة، أي ليس فيه حق يجب بسبب المال سوى الزكاة، وإلا ففيه واجبات بغير سبب المال، كما تجب النفقات للأقارب، والزوجة، والرقيق والبهائم، ويجب حمل العاقلة، ويجب قضاء الديون، ويجب الإعطاء في النائبة، ويجب إطعام الجائع وكسوة العاري فرضا على الكفاية، إلى غير ذلك من الواجبات المالية، لكن بسبب عارض، والمال شرط وجوبها، كالاستطاعة في الحج، فإن البدن سبب الوجوب والاستطاعة شرط، والمال في الزكاة هو السبب والوجوب معه، حتى لو لم يكن في بلده من يستحقها حملها إلى بلد أخرى، وهي حق وجب لله تعالى؛ ولهذا قال من قال من الفقهاء: إن التكليف شرط فيها، فلا تجب على الصغير والمجنون، وأما عامة الصحابة والجمهور، كمالك والشافعي وأحمد، فأوجبوها في مال الصغير والمجنون؛ لأن مالهما من جنس مال غيرهما ووليهما يقوم مقامهما، بخلاف بدنهما، فإنه إنما يتصرف بعقلهما، وعقلهما ناقص. وصار هذا كما يجب العشر في أرضهما مع أنه إنما يستحقه الثمانية، وكذلك إيجاب الكفارة في مالهما، والصلاة والصيام. إنما تسقط لعجز العقل عن الإيجاب، لا سيما إذا انضم إلى عجز البدن كالصغير. وهذا المعنى منتف في المال فإن الولي قام مقامهما في الفهم كما يقوم مقامهما في جميع ما يجب في المال، وأما بدنهما فلا يجب عليهما فيه شيء. فصل قال محمد بن نصر: واستدلوا على أن الإيمان هو ما ذكره بالآيات التي تلوناها عند ذكر تسمية الله الصلاة وسائر الطاعات إيمانا، واستدلوا أيضا بما قص الله من إباء إبليس حين عصى ربه في سجدة واحدة أمر أن يسجدها لآدم فأباها. فهل جحد إبليس ربه وهو يقول: {رب بمآ أغويتني} [الحجر: 39] ويقول: {رب فأنظرني إلى يوم يبعثون} [الحجر: 36] إيمانا منه بالبعث، وإيمانا بنفاذ قدرته في إنظاره إياه إلى يوم يبعثون؟ وهل جحد أحدا من أنبيائه أو أنكر شيئا من سلطانه وهو يحلف بعزته؟ وهل كان كفره إلا بترك سجدة واحدة أمر بها فأباها؟ قال: واستدلوا أيضا بما قص الله علينا من نبأ ابني آدم {إذ قربا قربانا فتقبل من أحدهما ولم يتقبل من الآخر} إلى قوله: {فأصبح من الخاسرين} [المائدة: 27: 30] ، قالوا: وهل جحد ربه؟ وكيف يجحده وهو يقرب القربان؟ . قالوا: قال الله تعالى: {إنما يؤمن بآياتنا الذين إذا ذكروا بها خروا سجدا وسبحوا بحمد ربهم وهم لا يستكبرون} [السجدة: 15] ، ولم يقل: إذا ذكروا بها أقروا بها فقط، وقال: {الذين آتيناهم الكتاب يتلونه حق تلاوته أولئك يؤمنون به} [البقرة: 121] يعني: يتبعونه حق اتباعه؟
A4: 3 | B4: Çok yüksek (likely birebir) | C4: MF-V07-S08-P007 | D4: IMN-S00-P107 | E4: 0.96 | F4: 0.945 | G4: 0.02 | H4: 0 | I4: S: V07P298–V07P327 T: V01P007–V01P359 | J4: لأنه لا يستحق هذا الاسم عنده إلا من أدى ما وجب عليه وانتهى عما حرم عليه من الموجبات للنار التي هي الكبائر. قالوا: فلما أبان الله أن هذا الاسم يستحقه من قد استحق الجنة وأن الله قد أوجب الجنة عليه. وعلمنا أنا قد آمنا وصدقنا؛ لأنه لا يخرج من التصديق إلا بالتكذيب؛ ولسنا بشاكين ولا مكذبين؛ وعلمنا أنا عاصون له مستوجبون للعذاب وهو ضد الثواب الذي حكم الله به للمؤمنين على اسم الإيمان؛ علمنا أنا قد آمنا وأمسكنا عن الاسم الذي أثبت الله عليه الحكم في الجنة وهو من الله اسم ثناء وتزكية وقد نهانا الله أن نزكي أنفسنا وأمرنا بالخوف على أنفسنا وأوجب لنا العذاب بعصياننا فعلمنا أنا لسنا بمستحقين بأن نتسمى مؤمنين إذ أوجب الله على اسم الإيمان الثناء والتزكية والرأفة والرحمة والمغفرة والجنة؛ وأوجب على الكبائر النار وهذان حكمان متضادان. فإن قيل: فكيف أمسكتم عن اسم الإيمان أن تسموا به وأنتم تزعمون أن أصل الإيمان في قلوبكم وهو التصديق بأن الله حق وما قاله صدق؟ قالوا: إن الله ورسوله وجماهير المسلمين سموا الأشياء بما غلب عليها من الأسماء فسموا الزاني فاسقا والقاذف فاسقا وشارب الخمر فاسقا ولم يسموا واحدا من هؤلاء متقيا ولا ورعا؛ وقد أجمع المسلمون أن فيه أصل التقوى والورع وذلك أنه يتقي أن يكفر أو يشرك بالله شيئا. وكذلك يتقي الله أن يترك الغسل من الجنابة أو الصلاة ويتقي أن يأتي أمه فهو في جميع ذلك متق وقد أجمع المسلمون من الموافقين والمخالفين أنهم لا يسمونه متقيا ولا ورعا إذا كان يأتي بالفجور فلما أجمعوا أن أصل التقى والورع ثابت فيه وأنه قد يزيد فيه فرعا بعد الأصل كتورعه عن إتيان المحارم ثم لا يسمونه متقيا ولا ورعا مع إتيانه بعض الكبائر بل سموه فاسقا وفاجرا مع علمهم أنه قد أتى ببعض التقى والورع فمنعهم من ذلك أن اسم التقى اسم ثناء وتزكية وأن الله قد أوجب عليه المغفرة والجنة. قالوا: فلذلك لا نسميه مؤمنا ونسميه فاسقا زانيا. وإن كان في قلبه أصل اسم الإيمان لأن الإيمان اسم أثنى الله به على المؤمنين وزكاهم به وأوجب عليه الجنة فمن ثم قلنا: مسلم ولم نقل: مؤمن قالوا: ولو كان أحد من المسلمين الموحدين يستحق ألا يكون في قلبه إيمان ولا إسلام لكان أحق الناس بذلك أهل النار الذين دخلوها فلما وجدنا النبي صلى الله عليه وسلم يخبر أن الله يقول: {أخرجوا من النار من كان في قلبه مثقال ذرة من إيمان} ثبت أن شر المسلمين في قلبه إيمان ولما وجدنا الأمة تحكم عليه بالأحكام التي ألزمها الله للمسلمين ولا يكفرونهم ولا يشهدون لهم بالجنة: ثبت أنهم مسلمون إذ أجمعوا أن يمضوا عليهم أحكام المسلمين وأنهم لا يستحقون أن يسموا مؤمنين إذ كان الإسلام يثبت للملة التي يخرج بها الإنسان من جميع الملل فتزول عنه أسماء الملل إلا اسم الإسلام وتثبت أحكام الإسلام عليه وتزول عنه أحكام جميع الملل. فإن قال لهم قائل: لم لم تقولوا: كافر إن شاء الله تريدون به كمال الكفر كما قلتم: مؤمنون إن شاء الله تريدون به كمال الإيمان؟ قالوا: لأن الكافر منكر للحق والمؤمن أصل إيمانه الإقرار، والإنكار لا أول له ولا آخر فتنتظر به الحقائق والإيمان أصله التصديق والإقرار ينتظر به حقائق الأداء لما أقر والتحقيق لما صدق؛ ومثل ذلك كمثل رجلين عليهما حق لرجل فسأل أحدهما حقه فقال: ليس لك عندي حق فأنكر وجحد فلم يبق له منزلة يحقق بها ما قال إذا جحد وأنكر وسأل الآخر حقه فقال: نعم لك علي كذا وكذا فليس إقراره بالذي يصل إليه بذلك حقه دون أن يوفيه؛ فهو منتظر له أن يحقق ما قال بالأداء ويصدق إقراره بالوفاء ولو أقر ثم لم يؤد إليه حقه كان كمن جحده في المعنى إذ استويا في الترك للأداء فتحقيق ما قال أن يؤدي إليه حقه؛ فإن أدى جزءا منه حقق بعض ما قال ووفى ببعض ما أقر به. وكلما أدى جزءا ازداد تحقيقا لما أقر به. وعلى المؤمن الأداء أبدا بما أقر به حتى يموت. فمن ثم قلنا: مؤمن إن شاء الله ولم نقل: كافر إن شاء الله. | K4: قال: ثم أوجب الله النار على الكبائر، فدل بذلك على أن اسم الإيمان زائل عمن أتى كبيرة. قالوا: ولم نجده أوجب الجنة باسم الإسلام، فثبت أن اسم الإسلام له ثابت على حاله، واسم الإيمان زائل عنه. فإن قيل لهم في قولهم هذا: ليس الإيمان ضد الكفر، قالوا: الكفر ضد لأصل الإيمان، لأن للإيمان أصلا وفروعا، فلا يثبت الكفر حتى يزول أصل الإيمان الذي هو ضد الكفر، فإن قيل لهم: فالذين زعمتم أن النبي صلى الله عليه وسلم أزال عنهم اسم الإيمان، هل فيهم من الإيمان شيء؟ قالوا: نعم أصله ثابت، ولولا ذلك لكفروا، ألم تسمع إلى ابن مسعود أنكر على الذي شهد أنه مؤمن ثم قال: لكنا نؤمن بالله وملائكته وكتبه ورسله يخبرك أنه قد آمن من جهة أنه صدق، وأنه لا يستحق اسم المؤمن إذا كان يعلم أنه مقصر، لأنه لا يستحق هذا الاسم عنده إلا من أدى ما وجب عليه وانتهى عما حرم عليه من الموجبات للنار التي هي الكبائر. قالوا: فلما أبان الله أن هذا الاسم يستحقه من قد استحق الجنة، وأن الله قد أوجب الجنة عليه، وعلمنا أنا قد آمنا وصدقنا؛ لأنه لا يخرج من التصديق إلا بالتكذيب، ولسنا بشاكين ولا مكذبين، وعلمنا أنا عاصون له مستوجبون للعذاب وهو ضد الثواب الذي حكم الله به للمؤمنين على اسم الإيمان علمنا أنا قد آمنا وأمسكنا عن الاسم الذي أثبت الله عليه الحكم في الجنة وهو من الله اسم ثناء وتزكية، وقد نهانا الله أن نزكي أنفسنا، وأمرنا بالخوف على أنفسنا، وأوجب لنا العذاب بعصياننا، فعلمنا أنا لسنا بمستحقين بأن نتسمى مؤمنين؛ إذ أوجب الله على اسم الإيمان الثناء والتزكية والرأفة والرحمة والمغفرة والجنة، وأوجب على الكبائر النار، وهذان حكمان متضادان. فإن قيل: فكيف أمسكتم عن اسم الإيمان أن تسموا به، وأنتم تزعمون أن أصل الإيمان في قلوبكم وهو التصديق بأن الله حق، وما قاله صدق؟ قالوا: إن الله ورسوله وجماهير المسلمين سموا الأشياء بما غلب عليها من الأسماء، فسموا الزاني فاسقا، والقاذف فاسقا وشارب الخمر فاسقا، ولم يسموا واحدا من هؤلاء متقيا ولا ورعا، وقد أجمع المسلمون أن فيه أصل التقوى والورع، وذلك أنه يتقي أن يكفر أو يشرك بالله شيئا، وكذلك يتقي الله أن يترك الغسل من الجنابة أوالصلاة، ويتقي أن يأتي أمه، فهو في جميع ذلك متق، وقد أجمعالمسلمون من الموافقين والمخالفين أنهم لا يسمونه متقيا ولا ورعا إذا كان يأتي بالفجور، فلما أجمعوا أن أصل التقي والورع ثابت فيه، وأنه قد يزيد فيه فرعا بعد الأصل كتورعه عن إتيان المحارم، ثم لا يسمونه متقيا ولا ورعا مع إتيانه بعض الكبائر، بل سموه فاسقا وفاجرا مع علمهم أنه قد أتى ببعض التقى والورع، فمنعهم من ذلك أن اسم التقي اسم ثناء وتزكية، وأن الله قد أوجب عليه المغفرة والجنة. قالوا: فلذلك لا نسميه مؤمنا ونسميه فاسقا زانيا، وإن كان في قلبه أصل اسم الإيمان؛ لأن الإيمان اسم أثنى الله به على المؤمنين وزكاهم به وأوجب عليه الجنة، فمن ثم قلنا: مسلم، ولم نقل: مؤمن، قالوا: ولو كان أحد من المسلمين الموحدين يستحق ألا يكون في قلبه إيمان ولا إسلام، لكان أحق الناس بذلك أهل النار الذين دخلوها، فلما وجدنا النبي صلى الله عليه وسلم يخبر أن الله يقول: " أخرجوا من النار من كان في قلبه مثقال ذرة من إيمان "، ثبت أن شر المسلمين في قلبه إيمان، ولما وجدنا الأمة تحكم عليه بالأحكام التي ألزمها الله للمسلمين ولا يكفرونهم، ولا يشهدون لهم بالجنة، ثبت أنهم مسلمون؛ إذ أجمعوا أن يمضوا عليهم أحكام المسلمين، وأنهم لا يستحقون أن يسموا مؤمنين؛ إذ كان الإسلام يثبت للملة التي يخرج بها الإنسان من جميع الملل، فتزول عنه أسماء الملل إلا اسم الإسلام، وتثبت أحكام الإسلام عليه، وتزول عنه أحكام جميع الملل. فإن قال لهم قائل: لم لم تقولوا: كافر إن شاء الله، تريدون به كمال الكفر، كما قلتم: مؤمنون إن شاء الله تريدون به كمال الإيمان؟ قالوا: لأن الكافر منكر للحق، والمؤمن أصل إيمانه الإقرار، والإنكار لا أول له ولا آخر فتنتظر به الحقائق، والإيمان أصله التصديق، والإقرار ينتظر به حقائق الأداء لما أقر، والتحقيق لما صدق، ومثل ذلك كمثل رجلين عليهما حق لرجل، فسأل أحدهما حقه، فقال: ليس لك عندي حق، فأنكر وجحد فلم يبق له منزلة يحقق بها ما قال إذا جحد وأنكر، وسأل الآخر حقه فقال: نعم لك علي كذا وكذا، فليس إقراره بالذي يصل إليه بذلك حقه دون أن يوفيه، فهو منتظر له أن يحقق ما قال بالأداء ويصدق إقراره بالوفاء، ولو أقر ثم لم يؤد إليه حقه كان كمن جحده في المعنى إذ استويا في الترك للأداء، فتحقيق ما قال أن يؤدي إليه حقه، فإن أدى جزءا منه حقق بعض ما قال ووفى ببعض ما أقر به. وكلما أدى جزءا ازداد تحقيقا لما أقر به، وعلى المؤمن الأداء أبدا بما أقر به حتى يموت. فمن ثم قلنا: مؤمن إن شاء الله، ولم نقل: كافر إن شاء الله.
A5: 4 | B5: Çok yüksek (likely birebir) | C5: MF-V07-S09-P025 | D5: IMN-S00-P136 | E5: 0.964 | F5: 0.964 | G5: 0 | H5: 0 | I5: S: V07P328–V07P417 T: V01P007–V01P359 | J5: وسائر المرجئة وهو أن الشيء المركب إذا زال بعض أجزائه لزم زواله كله؛ لكن هو لم يذكر إلا ظاهر شبهتهم. والجواب عما ذكروه هو سهل فإنه يسلم له أن الهيئة الاجتماعية لم تبق مجتمعة كما كانت؛ لكن لا يلزم من زوال بعضها زوال سائر الأجزاء. والشافعي مع الصحابة والتابعين وسائر السلف يقولون: إن الذنب يقدح في كمال الإيمان ولهذا نفى الشارع الإيمان عن هؤلاء فذلك المجموع الذي هو الإيمان لم يبق مجموعا مع الذنوب لكن يقولون بقي بعضه: إما أصل وإما أكثره وإما غير ذلك فيعود الكلام إلى أنه يذهب بعضه ويبقى بعضه. ولهذا كانت المرجئة تنفر من لفظ النقص أعظم من نفورها من لفظ الزيادة؛ لأنه إذا نقص لزم ذهابه كله عندهم إن كان متبعضا متعددا عند من يقول بذلك وهم الخوارج والمعتزلة. وإما الجهمية فهو واحد عندهم لا يقبل التعدد؛ فيثبتون واحدا لا حقيقة له؛ كما قالوا مثل ذلك في وحدانية الرب ووحدانية صفاته عند من أثبتها منهم ومن العجب أن الأصل الذي أوقعهم في هذا اعتقادهم أنه لا يجتمع في الإنسان بعض الإيمان وبعض الكفر أو ما هو إيمان وما هو كفر واعتقدوا أن هذا متفق عليه بين المسلمين كما ذكر ذلك أبو الحسن وغيره فلأجل اعتقادهم هذا الإجماع وقعوا فيما هو مخالف للإجماع الحقيقي إجماع السلف الذي ذكره غير واحد من الأئمة؛ بل وصرح غير واحد منهم بكفر من قال بقول جهم في الإيمان. ولهذا نظائر متعددة؛ يقول الإنسان قولا مخالفا للنص والإجماع القديم حقيقة ويكون معتقدا أنه متمسك بالنص والإجماع. وهذا إذا كان مبلغ علمه واجتهاده؛ فالله يثيبه على ما أطاع الله فيه من اجتهاده ويغفر له ما عجز عن معرفته من الصواب الباطن وهم لما توهموا أن الإيمان الواجب على جميع الناس نوع واحد؛ صار بعضهم يظن أن ذلك النوع من حيث هو لا يقبل التفاضل. فقال لي مرة بعضهم: الإيمان من حيث هو إيمان لا يقبل الزيادة والنقصان. فقلت له: قولك من حيث هو؛ كما تقول: الإنسان من حيث هو إنسان والحيوان من حيث هو حيوان والوجود من حيث هو وجود والسواد من حيث هو سواد وأمثال ذلك لا يقبل الزيادة والنقصان والصفات؛ فتثبت لهذه المسميات وجودا مطلقا مجردا عن جميع القيود والصفات وهذا لا حقيقة له في الخارج وإنما هو شيء يقدره الإنسان في ذهنه كما يقدر موجودا لا قديما ولا حادثا ولا قائما بنفسه ولا بغيره ويقدر إنسانا لا موجودا ولا معدوما ويقول: الماهية من حيث هي هي لا توصف بوجود ولا عدم والماهية من حيث هي هي شيء يقدره الذهن وذلك موجود في الذهن لا في الخارج. وأما تقدير شيء لا يكون في الذهن ولا في الخارج فممتنع وهذا التقدير لا يكون إلا في الذهن كسائر تقدير الأمور الممتنعة؛ مثل تقدير صدور العالم عن صانعين ونحو ذلك؛ فإن هذه المقدرات في الذهن. فهكذا تقدير إيمان لا يتصف به مؤمن؛ بل هو مجرد عن كل قيد. وتقدير إنسان لا يكون موجودا ولا معدوما؛ بل ما ثم إيمان إلا مع المؤمنين ولا ثم إنسانية إلا ما اتصف بها الإنسان؛ فكل إنسان له إنسانية تخصه وكل مؤمن له إيمان يخصه؛ فإنسانية زيد تشبه إنسانية عمر وليست هي هي. وإذا اشتركوا في نوع الإنسانية فمعنى ذلك أنهما يشتبهان فيما يوجد في الخارج ويشتركان في أمر كلي مطلق يكون في الذهن. وكذلك إذا قيل: إيمان زيد مثل إيمان عمرو؛ فإيمان كل واحد يخصه. فلو قدر أن الإيمان يتماثل لكان لكل مؤمن إيمان يخصه وذلك الإيمان مختص معين ليس هو الإيمان من حيث هو هو؛ بل هو إيمان معين وذلك الإيمان يقبل الزيادة. والذين ينفون التفاضل في هذه الأمور يتصورون في أنفسهم إيمانا مطلقا أو إنسانا مطلقا أو وجودا مطلقا مجردا عن جميع الصفات المعينة له ثم يظنون أن هذا هو الإيمان الموجود في الناس وذلك لا يقبل التفاضل ولا يقبل في نفسه التعدد؛ إذ هو تصور معين قائم في نفس متصوره. ولهذا يظن كثير من هؤلاء أن الأمور المشتركة في شيء واحد هي واحدة بالشخص والعين. حتى انتهى الأمر بطائفة من علمائهم علما وعبادة إلى أن جعلوا الوجود كذلك؛ فتصوروا أن الموجودات مشتركة في مسمى الوجود وتصوروا هذا في أنفسهم فظنوه في الخارج كما هو في أنفسهم ثم ظنوا أنه الله؛ فجعلوا الرب هو هذا الوجود الذي لا يوجد قط إلا في نفس متصوره؛ ولا يكون في الخارج. | K5: والشافعي مع الصحابة والتابعين وسائر السلف يقولون: إن الذنب يقدح في كمال الإيمان، ولهذا نفى الشارع الإيمان عن هؤلاء، فذلك المجموع الذي هو الإيمان لم يبق مجموعا مع الذنوب، لكن يقولون بقى بعضه؛ إما أصله وإما أكثره وإما غير ذلك، فيعود الكلام إلى أنه يذهب بعضه ويبقى بعضه. ولهذا كانت المرجئة تنفر من لفظ النقص أعظم من نفورها من لفظ الزيادة؛ لأنه إذا نقص لزم ذهابه كله عندهم إن كان متبعضا متعددا عند من يقول بذلك، وهم الخوارج والمعتزلة. وأما الجهمية فهو واحد عندهم لا يقبل التعدد، فيثبتون واحدا لا حقيقة له، كما قالوا مثل ذلك في وحدانية الرب ووحدانية صفاته عند من أثبتها منهم. ومن العجب أن الأصل الذي أوقعهم في هذا، اعتقادهم أنه لا يجتمع في الإنسان بعض الإيمان وبعض الكفر، أو ما هو إيمان وما هو كفر، واعتقدوا أن هذا متفق عليه بين المسلمين كما ذكر ذلك أبو الحسن وغيره، فلأجل اعتقادهم هذا الإجماع وقعوا فيما هو مخالف للإجماع الحقيقي، إجماعالسلف الذي ذكره غير واحد من الأئمة بل وصرح غير واحد منهم بكفر من قال بقول جهم في الإيمان. ولهذا نظائر متعددة، يقول الإنسان قولا مخالفا للنص والإجماع القديم حقيقة، ويكون معتقدا أنه متمسك بالنص والإجماع. وهذا إذا كان مبلغ علمه واجتهاده، فالله يثيبه على ما أطاع الله فيه من اجتهاده، ويغفر له ما عجز عن معرفته من الصواب الباطن، وهم لما توهموا أن الإيمان الواجب على جميع الناس نوع واحد، صار بعضهم يظن أن ذلك النوع من حيث هو لا يقبل التفاضل. فقال لي مرة بعضهم: الإيمان من حيث هو إيمان لا يقبل الزيادة والنقصان. فقلت له: قولك من حيث هو، كما تقول: الإنسان من حيث هو إنسان، والحيوان من حيث هو حيوان، والوجود من حيث هو وجود، والسواد من حيث هو سواد، وأمثال ذلك لا يقبل الزيادة والنقصان والصفات، فتثبت لهذه المسميات وجودا مطلقا مجردا عن جميع القيود والصفات وهذا لا حقيقة له في الخارج، وإنما هو شيء يقدره الإنسان في ذهنه، كما يقدر موجودا لا قديما ولا حادثا ولا قائما بنفسه ولا بغيره، ويقدر إنسانا لا موجودا ولا معدوما، ويقول: الماهية من حيث هي هي لا توصف بوجود ولا عدم، والماهية من حيث هي هي شيء يقدره الذهن، وذلك موجود في الذهن لا في الخارج، وأما تقدير شيء لا يكون في الذهن ولا في الخارج فممتنع، وهذا التقدير لا يكون إلا في الذهن كسائر تقدير الأمور الممتنعة، مثل تقدير صدور العالم عن صانعين ونحو ذلك، فإن هذه المقدرات في الذهن. فهكذا تقدير إيمان لا يتصف به مؤمن، بل هو مجرد عن كل قيد. وتقدير إنسان لا يكون موجودا ولا معدوما، بل ما ثم إيمان إلا مع المؤمنين، ولا ثم إنسانية إلا ما اتصف بها الإنسان، فكل إنسان له إنسانية تخصه، وكل مؤمن له إيمان يخصه، فإنسانية زيد تشبه إنسانية عمرو، ليست هي هي. وإذا اشتركوا في نوع الإنسانية فمعنى ذلك أنهما يشتبهان فيما يوجد في الخارج، ويشتركان في أمر كلي مطلق يكون في الذهن. وكذلك إذا قيل: إيمان زيد مثل إيمان عمرو، فإيمان كل واحد يخصه، فلو قدر أن الإيمان يتماثل لكان لكل مؤمن إيمان يخصه، وذلك الإيمان مختص معين ليس هو الإيمان من حيث هو هو، بل هو إيمان معين، وذلك الإيمان يقبل الزيادة، والذين ينفون التفاضل في هذه الأمور يتصورون في أنفسهم إيمانا مطلقا أو إنسانا مطلقا، أو وجودا مطلقا مجردا عن جميع الصفات المعينة له ثم يظنون أن هذا هو الإيمان الموجود في الناس. وذلك لا يقبل التفاضل ولا يقبل في نفسه التعدد، إذ هو تصور معين قائم في نفس متصوره. ولهذا يظن ثير من هؤلاء أن الأمور المشتركة في شيء واحد هي واحدة بالشخص والعين، حتى انتهى الأمر بطائفة من علمائهم علما وعبادة إلى أن جعلوا الوجود كذلك، فتصوروا أن الموجودات مشتركة في مسمى الوجود، وتصوروا هذا في أنفسهم، فظنوه في الخارج كما هو في أنفسهم، ثم ظنوا أنه الله، فجعلوا الرب هو هذا الوجود الذي لا يوجد قط إلا في نفس متصوره، ولا يكون في الخارج.
A6: 5 | B6: Çok yüksek (likely birebir) | C6: MF-V07-S07-P008 | D6: IMN-S00-P095 | E6: 0.968 | F6: 0.934 | G6: 0.03 | H6: 0 | I6: S: V07P259–V07P297 T: V01P007–V01P359 | J6: قالها لذهب عنه ما يجد أعوذ بالله من الشيطان الرجيم} فأمر سبحانه بالاستعاذة عند طلب العبد الخير لئلا يعوقه الشيطان عنه؛ وعند ما يعرض عليه من الشر ليدفعه عنه عند إرادة العبد للحسنات؛ وعند ما يأمره الشيطان بالسيئات. ولهذا قال النبي صلى الله عليه وسلم {لا يزال الشيطان يأتي أحدكم فيقول: من خلق كذا؟ من خلق كذا؟ حتى يقول: من خلق الله؟ فمن وجد ذلك فليستعذ بالله ولينته} فأمر بالاستعاذة عندما يطلب الشيطان أن يوقعه في شر أو يمنعه من خير؛ كما يفعل العدو مع عدوه. وكلما كان الإنسان أعظم رغبة في العلم والعبادة وأقدر على ذلك من غيره بحيث تكون قوته على ذلك أقوى ورغبته وإرادته في ذلك أتم؛ كان ما يحصل له إن سلمه الله من الشيطان أعظم؛ وكان ما يفتتن به إن تمكن منه الشيطان أعظم. ولهذا قال الشعبي: كل أمة علماؤها شرارها إلا المسلمين فإن علماءهم خيارهم. وأهل السنة في الإسلام؛ كأهل الإسلام في الملل؛ وذلك أن كل أمة غير المسلمين فهم ضالون وإنما يضلهم علماؤهم؛ فعلماؤهم شرارهم والمسلمون على هدى وإنما يتبين الهدى بعلمائهم فعلماؤهم خيارهم؛ وكذلك أهل السنة أئمتهم خيار الأمة وأئمة أهل البدع أضر على الأمة من أهل الذنوب. ولهذا أمر النبي صلى الله عليه وسلم بقتل الخوارج؛ ونهى عن قتال الولاة الظلمة؛ وأولئك لهم نهمة في العلم والعبادة؛ فصار يعرض لهم من الوساوس التي تضلهم - وهم يظنونها هدى فيطيعونها - ما لا يعرض لغيرهم ومن سلم من ذلك منهم كان من أئمة المتقين مصابيح الهدى وينابيع العلم؛ كما قال ابن مسعود لأصحابه: كونوا ينابيع العلم مصابيح الحكمة سرج الليل؛ جدد القلوب أحلاس البيوت خلقان الثياب؛ تعرفون في أهل السماء وتخفون على أهل الأرض. فصل: ومما ينبغي أن يعلم أن الألفاظ الموجودة في القرآن والحديث إذا عرف تفسيرها وما أريد بها من جهة النبي صلى الله عليه وسلم لم يحتج في ذلك إلى الاستدلال بأقوال أهل اللغة ولا غيرهم؛ ولهذا قال الفقهاء: " الأسماء ثلاثة أنواع " نوع يعرف حده بالشرع كالصلاة والزكاة؛ ونوع يعرف حده باللغة كالشمس والقمر؛ ونوع يعرف حده بالعرف كلفظ القبض ولفظ المعروف في قوله: {وعاشروهن بالمعروف} ونحو ذلك. وروي عن ابن عباس أنه قال: تفسير القرآن على أربعة أوجه: تفسير تعرفه العرب من كلامها وتفسير لا يعذر أحد بجهالته وتفسير يعلمه العلماء وتفسير لا يعلمه إلا الله من ادعى علمه فهو كاذب. فاسم الصلاة والزكاة والصيام والحج ونحو ذلك قد بين الرسول صلى الله عليه وسلم ما يراد بها في كلام الله ورسوله وكذلك لفظ الخمر وغيرها ومن هناك يعرف معناها فلو أراد أحد أن يفسرها بغير ما بينه النبي صلى الله عليه وسلم لم يقبل منه وأما الكلام في اشتقاقها ووجه دلالتها فذاك من جنس علم البيان. وتعليل الأحكام هو زيادة في العلم وبيان حكمة ألفاظ القرآن؛ لكن معرفة المراد بها لا يتوقف على هذا. واسم الإيمان والإسلام والنفاق والكفر هي أعظم من هذا كله؛ فالنبي صلى الله عليه وسلم قد بين المراد بهذه الألفاظ بيانا لا يحتاج معه إلى الاستدلال على ذلك بالاشتقاق وشواهد استعمال العرب ونحو ذلك؛ فلهذا يجب الرجوع في مسميات هذه الأسماء إلى بيان الله ورسوله فإنه شاف كاف؛ بل معاني هذه الأسماء معلومة من حيث الجملة للخاصة والعامة بل كل من تأمل ما تقوله الخوارج والمرجئة في معنى الإيمان علم بالاضطرار أنه مخالف للرسول ويعلم بالاضطرار أن طاعة الله ورسوله من تمام الإيمان وأنه لم يكن يجعل كل من أذنب ذنبا كافرا ويعلم أنه لو قدر أن قوما قالوا للنبي صلى الله عليه وسلم نحن نؤمن بما جئتنا به بقلوبنا من غير شك؛ ونقر بألسنتنا بالشهادتين إلا أنا لا نطيعك في شيء مما أمرت به ونهيت عنه فلا نصلي ولا نصوم ولا نحج ولا نصدق الحديث ولا نؤدي الأمانة ولا نفي بالعهد ولا نصل الرحم ولا نفعل شيئا من الخير الذي أمرت به ونشرب الخمر؛ وننكح ذوات المحارم بالزنا الظاهر ونقتل من قدرنا عليه من أصحابك وأمتك ونأخذ أموالهم بل نقتلك أيضا ونقاتلك مع أعدائك؛ هل كان يتوهم عاقل أن النبي صلى الله عليه وسلم يقول لهم: أنتم مؤمنون كاملو الإيمان وأنتم من أهل شفاعتي يوم القيامة ويرجى لكم ألا يدخل أحد منكم النار بل كل مسلم يعلم بالاضطرار أنه يقول لهم: أنتم أكفر الناس بما جئت به ويضرب رقابهم إن لم يتوبوا من ذلك. وكذلك كل مسلم يعلم أن شارب الخمر والزاني والقاذف والسارق لم يكن النبي صلى الله عليه وسلم يجعلهم مرتدين يجب قتلهم بل القرآن والنقل المتواتر عنه يبين أن هؤلاء لهم عقوبات غير عقوبة المرتد عن الإسلام | K6: وفي الصحيحين عن النبي صلى الله عليه وسلم أنه قال: " إني لأعلم كلمة لو قالها لذهب عنه ما يجد: أعوذ بالله من الشيطان الرجيم ". فأمر سبحانه بالاستعاذة عند طلب العبد الخير؛ لئلا يعوقه الشيطان عنه، وعندما يعرض عليه من الشر ليدفعه عنه عند إرادة العبد للحسنات، وعند ما يأمره الشيطان بالسيئات؛ ولهذا قال النبي صلى الله عليه وسلم: " لا يزال الشيطان يأتي أحدكم فيقول: من خلق كذا؟ من خلق كذا؟ حتى يقول: من خلق الله؟ فمن وجد ذلك فليستعذ بالله ولينته "، فأمر بالاستعاذة عندما يطلب الشيطان أن يوقعه في شر أو يمنعه من خير، كما يفعل العدو مع عدوه. وكلما كان الإنسان أعظم رغبة في العلم والعبادة، وأقدر على ذلك من غيره بحيث تكون قوته على ذلك أقوى، ورغبته وإرادته في ذلك أتم، كان ما يحصل له إن سلمه الله من الشيطان أعظم، وكان ما يفتتن به إن تمكن منه الشيطان أعظم؛ ولهذا قال الشعبي: كل أمة علماؤها شرارها، إلا المسلمين فإن علماءهم خيارهم. وأهل السنة في الإسلام، كأهل الإسلام في الملل، وذلك أن كل أمة غير المسلمين فهم ضالون، وإنما يضلهم علماؤهم؛ فعلماؤهم شرارهم، والمسلمون على هدى، وإنما يتبين الهدى بعلمائهم، فعلماؤهم خيارهم، وكذلك أهل السنة، أئمتهم خيار الأمة، وأئمة أهل البدع أضر على الأمة من أهل الذنوب، ولهذا أمر النبي صلىالله عليه وسلم بقتل الخوارج، ونهى عن قتال الولاة الظلمة؛ وأولئك لهمنهمة في العلم والعبادة، فصار يعرض لهم من الوساوس التي تضلهم وهم يظنونها هدي، فيطيعونها ما لا يعرض لغيرهم، ومن سلم من ذلك منهم كان من أئمة المتقين مصابيح الهدى، وينابيع العلم؛ كما قال ابن مسعود لأصحابه: كونوا ينابيع العلم، مصابيح الحكمة، سرج الليل، جدد القلوب، أحلاس البيوت، خلقان الثياب، تعرفون في أهل السماء، وتخفون على أهل الأرض. فصل ومما ينبغي أن يعلم: أن الألفاظ الموجودة في القرآن والحديث، إذا عرف تفسيرها وما أريد بها من جهة النبي صلى الله عليه وسلم لم يحتج في ذلك إلى الاستدلال بأقوال أهل اللغة ولا غيرهم؛ ولهذا قال الفقهاء: [الأسماء ثلاثة أنواع] نوع يعرف حده بالشرع؛ كالصلاة والزكاة. ونوع يعرف حده باللغة؛ كالشمس والقمر. ونوع يعرف حده بالعرف كلفظ القبض، ولفظ المعروف في قوله: {وعاشروهن بالمعروف} [النساء: 19] ، ونحو ذلك. وروي عن ابن عباس أنه قال: تفسير القرآن على أربعة أوجه: تفسير تعرفه العرب من كلامها، وتفسير لا يعذر أحد بجهالته، وتفسير يعلمه العلماء، وتفسير لا يعلمه إلا الله، من ادعي علمه فهو كاذب. فاسم الصلاة والزكاة والصيام والحج ونحو ذلك، قد بين الرسول صلى الله عليه وسلم ما يراد بها في كلام الله ورسوله، وكذلك لفظ الخمر وغيرها، ومن هناك يعرف معناها، فلو أراد أحد أن يفسرها بغير ما بينه النبي صلى الله عليه وسلم لم يقبل منه، وأما الكلام في اشتقاقها ووجه دلالتها، فذاك من جنس علم البيان. وتعليل الأحكام، هو زيادة في العلم، وبيان حكمة ألفاظ القرآن؛ لكن معرفة المراد بها لا يتوقف على هذا. واسم الإيمان والإسلام والنفاق والكفر، هي أعظم من هذا كله، فالنبي صلى الله عليه وسلم قد بين المراد بهذه الألفاظ بيانا لا يحتاج معه إلى الاستدلال على ذلك بالاشتقاق وشواهد استعمال العرب ونحو ذلك؛ فلهذا يجب الرجوع في مسميات هذه الأسماء إلى بيان الله ورسوله، فإنه شاف كاف، بل معاني هذه الأسماء معلومة من حيث الجملة للخاصة والعامة، بل كل من تأمل ما تقوله الخوارج والمرجئة في معنى الإيمان، علم بالاضطرار أنه مخالف للرسول، ويعلم بالاضطرار أن طاعة الله ورسوله من تمام الإيمان، وأنه لم يكن يجعل كل من أذنب ذنبا كافرا، ويعلم أنه لو قدر أن قوما قالوا للنبي صلى الله عليه وسلم: نحن نؤمن بما جئتنا به بقلوبنا من غير شك، ونقر بألسنتنا بالشهادتين، إلا أنا لا نطيعك في شيء مما أمرت به ونهيت عنه، فلا نصلي ولا نصوم ولا نحج، ولا نصدق الحديث، ولا نؤدي الأمانة، ولا نفي بالعهد، ولا نصل الرحم، ولا نفعل شيئا من الخير الذي أمرت به، ونشرب الخمر؛ وننكح ذوات المحارم بالزنا الظاهر، ونقتل من قدرنا عليه من أصحابك وأمتك، ونأخذ أموالهم، بل نقتلك أيضا ونقاتلك مع أعدائك، هل كان يتوهم عاقل أن النبي صلى الله عليه وسلم يقول لهم: أنتم مؤمنون كاملو الإيمان، وأنتم من أهل شفاعتي يوم القيامة، ويرجى لكم ألا يدخل أحد منكم النار، بل كل مسلم يعلم بالاضطرار أنه يقول لهم: أنتم أكفر الناس بما جئت به، ويضرب رقابهم إن لم يتوبوا من ذلك.
A7: 6 | B7: Yüksek (büyük ihtimal düzenlenmiş tekrar) | C7: MF-V07-S06-P004 | D7: IMN-S00-P069 | E7: 0.911 | F7: 0.732 | G7: 0.2 | H7: 0.12 | I7: S: V07P195–V07P258 T: V01P007–V01P359 | J7: أهل الإرجاء بآية أحج من قوله: {وما أمروا إلا ليعبدوا الله مخلصين له الدين حنفاء ويقيموا الصلاة ويؤتوا الزكاة وذلك دين القيمة} . وقال الشافعي رضي الله عنه في كتاب " الأم " في (باب النية في الصلاة: يحتج بأن لا تجزئ صلاة إلا بنية بحديث عمر بن الخطاب رضي الله عنه عن النبي صلى الله عليه وسلم " {إنما الأعمال بالنيات} " ثم قال: وكان الإجماع من الصحابة والتابعين من بعدهم ومن أدركناهم يقولون: الإيمان قول وعمل ونية لا يجزئ واحد من الثلاث إلا بالآخر. وقال حنبل: حدثنا الحميدي قال: وأخبرت أن ناسا يقولون: من أقر بالصلاة والزكاة والصوم والحج ولم يفعل من ذلك شيئا حتى يموت ويصلي مستدبر القبلة حتى يموت؛ فهو مؤمن ما لم يكن جاحدا إذا علم أن تركه ذلك فيه إيمانه إذا كان مقرا بالفرائض واستقبال القبلة فقلت: هذا الكفر الصراح وخلاف كتاب الله وسنة رسوله وعلماء المسلمين. قال الله تعالى: {وما أمروا إلا ليعبدوا الله مخلصين له الدين} الآية. وقال حنبل: سمعت أبا عبد الله أحمد بن حنبل يقول: من قال هذا فقد كفر بالله ورد على أمره وعلى الرسول ما جاء به عن الله. قلت: وأما احتجاجهم بقوله للأمة " {أعتقها فإنها مؤمنة} " فهو من حججهم المشهورة وبه احتج ابن كلاب وكان يقول: الإيمان هو التصديق والقول جميعا فكان قوله أقرب من قول جهم وأتباعه وهذا لا حجة فيه؛ لأن الإيمان الظاهر الذي تجري عليه الأحكام في الدنيا لا يستلزم الإيمان في الباطن الذي يكون صاحبه من أهل السعادة في الآخرة فإن المنافقين الذين قالوا: {آمنا بالله وباليوم الآخر وما هم بمؤمنين} هم في الظاهر مؤمنون يصلون مع الناس. ويصومون ويحجون ويغزون والمسلمون يناكحونهم ويوارثونهم كما كان المنافقون على عهد رسول الله صلى الله عليه وسلم ولم يحكم النبي صلى الله عليه وسلم في المنافقين بحكم الكفار المظهرين للكفر لا في مناكحتهم ولا موارثتهم ولا نحو ذلك؛ بل لما مات عبد الله بن أبي ابن سلول - وهو من أشهر الناس بالنفاق - ورثه ابنه عبد الله وهو من خيار المؤمنين وكذلك سائر من كان يموت منهم يرثه ورثته المؤمنون؛ وإذا مات لأحدهم. وارث ورثوه مع المسلمين. وقد تنازع الفقهاء في المنافق الزنديق الذي يكتم زندقته هل يرث ويورث؟ على قولين والصحيح أنه يرث ويورث وإن علم في الباطن أنه منافق كما كان الصحابة على عهد النبي صلى الله عليه وسلم لأن الميراث مبناه على الموالاة الظاهرة لا على المحبة التي في القلوب فإنه لو علق بذلك لم تمكن معرفته والحكمة إذا كانت خفية أو منتشرة علق الحكم بمظنتها وهو ما أظهره من موالاة المسلمين؛ فقول النبي صلى الله عليه وسلم {لا يرث المسلم الكافر ولا الكافر المسلم} " لم يدخل فيه المنافقون وإن كانوا في الآخرة في الدرك الأسفل من النار؛ بل كانوا يورثون ويرثون؛ وكذلك كانوا في الحقوق والحدود كسائر المسلمين وقد أخبر الله عنهم أنهم يصلون ويزكون ومع هذا لم يقبل ذلك منهم فقال: {وما منعهم أن تقبل منهم نفقاتهم إلا أنهم كفروا بالله وبرسوله ولا يأتون الصلاة إلا وهم كسالى ولا ينفقون إلا وهم كارهون} وقال {إن المنافقين يخادعون الله وهو خادعهم وإذا قاموا إلى الصلاة قاموا كسالى يراءون الناس ولا يذكرون الله إلا قليلا} . وفي " صحيح مسلم " عن النبي صلى الله عليه وسلم قال: " {تلك صلاة المنافق تلك صلاة المنافق تلك صلاة المنافق يرقب الشمس حتى إذا كانت بين قرني شيطان قام فنقر أربعا لا يذكر الله فيها إلا قليلا} " وكانوا يخرجون مع النبي صلى الله عليه وسلم في المغازي كما خرج ابن أبي في غزوة بني المصطلق وقال فيها: {لئن رجعنا إلى المدينة ليخرجن الأعز منها الأذل} . " وفي الصحيحين " عن {زيد بن أرقم قال: خرجنا مع النبي صلى الله عليه وسلم في سفر أصاب الناس فيها شدة؛ فقال عبد الله بن أبي لأصحابه: لا تنفقوا على من عند رسول الله حتى ينفضوا من حوله. وقال: {لئن رجعنا إلى المدينة ليخرجن الأعز منها الأذل} فأتيت النبي صلى الله عليه وسلم فأخبرته فأرسل إلى عبد الله بن أبي؛ فسأله فاجتهد يمينه ما فعل وقالوا: كذب زيد يا رسول الله فوقع في نفسي مما قالوا شدة حتى أنزل الله تصديقي في {إذا جاءك المنافقون} فدعاهم النبي صلى الله عليه وسلم ليستغفر لهم فلووا رءوسهم. وفي غزوة تبوك استنفرهم النبي صلى الله عليه وسلم كما استنفر غيرهم فخرج بعضهم معه وبعضهم تخلفوا وكان في الذين خرجوا معه من هم بقتله في الطريق هموا بحل حزام | K7: أخذ الشافعي هذه الحجة عن عطاء. فروى ابن أبي حاتم في مناقب الشافعي: حدثنا أبي، حدثنا ميمون، حدثنا أبو عثمان بن الشافعي، سمعت أبي يقول ليلة للحميدي: ما يحتج عليهم يعني أهل الإرجاء بآية أحج من قوله: {وما أمروا إلا ليعبدوا الله مخلصين له الدين حنفاء ويقيموا الصلاة ويؤتوا الزكاة وذلك دين القيمة} [البينة: 5] . وقال الشافعي رضي الله عنه في كتاب [الأم] في [باب النية في الصلاة] : يحتج بألا تجزئ صلاة إلا بنية بحديث عمر بن الخطاب رضي الله عنه عن النبي صلى الله عليه وسلم: " إنما الأعمال بالنيات " ثم قال: وكان الإجماع من الصحابة، والتابعين من بعدهم، ومن أدركناهم يقولون: الإيمان قول وعمل ونية، لا يجزئ واحد من الثلاث إلا بالآخر. وقال حنبل: حدثنا الحميدي قال: وأخبرت أن ناسا يقولون: من أقر بالصلاة والزكاة والصوم والحج ولم يفعل من ذلك شيئا حتى يموت، ويصلي مستدبر القبلة حتى يموت، فهو مؤمن ما لم يكن جاحدا إذا علم أن تركه ذلك فيه إيمانه إذا كان مقرا بالفرائض واستقبال القبلة، فقلت: هذا الكفر الصراح، وخلاف كتاب الله وسنة رسوله وعلماء المسلمين، قال الله تعالى: {وما أمروا إلا ليعبدوا الله مخلصين له الدين} الآية. وقال حنبل: سمعت أبا عبد الله أحمد بن حنبل يقول: من قال هذا فقد كفر بالله، ورد على أمره وعلى الرسول ما جاء به عن الله. قلت: وأما احتجاجهم بقوله للأمة: " اعتقها فإنها مؤمنة " فهو من حججهم المشهورة، وبه احتج ابن كلاب، وكان يقول: الإيمان هو التصديق والقول جميعا، فكان قوله أقرب من قول جهم وأتباعه، وهذا لا حجة فيه؛ لأن الإيمان الظاهر الذي تجري عليه الأحكام في الدنيا لا يستلزم الإيمان في الباطن الذي يكون صاحبه من أهل السعادة في الآخرة، فإن المنافقين الذين قالوا: {آمنا بالله وباليوم الآخر وما هم بمؤمنين} [البقرة: 8] هم في الظاهر مؤمنون يصلون مع الناس، ويصومون ويحجون ويغزون، والمسلمون يناكحونهم ويوارثونهم كما كان المنافقون في عهد رسول الله صلىالله عليه وسلم، ولم يحكم النبي صلىالله عليه وسلم في المنافقين بحكم الكفار المظهرين للكفر، لا في مناكحتهم ولا موارثتهم ولا نحو ذلك، بل لما مات عبد الله بن أبي بن سلول وهو من أشهر الناس بالنفاق ورثه ابنه عبد الله وهو من خيار المؤمنين، وكذلك سائر من كان يموت منهم يرثه ورثته المؤمنون، وإذا مات لأحدهم وارث ورثوه مع المسلمين. وقد تنازع الفقهاء في المنافق الزنديق الذي يكتم زندقته، هل يرث ويورث؟ على قولين، والصحيح: أنه يرث ويورث وإن علم في الباطن أنه منافق، كما كان الصحابة على عهد النبي صلىالله عليه وسلم؛ لأن الميراث مبناه على الموالاة الظاهرة، لا على المحبة التي في القلوب، فإنه لو علق بذلك لم تمكن معرفته، والحكمة إذا كانت خفية أو منتشرة علق الحكم بمظنتها، وهو ما أظهره من موالاة المسلمين فقول النبي صلىالله عليه وسلم: " لا يرث المسلم الكافر ولا الكافر المسلم " لم يدخل فيه المنافقون وإن كانوا في الآخرة في الدرك الأسفل من النار، بل كانوا يورثون ويرثون، وكذلك كانوا في الحقوق والحدود كسائر المسلمين، وقد أخبر الله عنهم أنهم يصلون ويزكون ومع هذا لم يقبل ذلك منهم فقال: {وما منعهم أن تقبل منهم نفقاتهم إلا أنهم كفروا بالله وبرسوله ولا يأتون الصلاة إلا وهم كسالى ولا ينفقون إلا وهم كارهون} [التوبة: 54] ، وقال: {إن المنافقين يخادعون الله وهو خادعهم وإذا قاموا إلى الصلاة قاموا كسالى يرآؤون الناس ولا يذكرون الله إلا قليلا} [النساء: 142] . وفي صحيح مسلم عن النبي صلى الله عليه وسلم قال: " تلك صلاة المنافق، تلك صلاة المنافق، تلك صلاة المنافق، يرقب الشمس حتى إذا كانت بين قرني شيطان قام فنقر أربعا لا يذكر الله فيها إلا قليلا "، وكانوا يخرجون مع النبي صلىالله عليه وسلم في المغازي، كما خرج ابن أبي في غزوة بني المصطلق، وقال فيها: {لئن رجعنا إلى المدينة ليخرجن الأعز منها الأذل} [المنافقون: 8] . وفي الصحيحين عن زيد بن أرقم قال: خرجنا مع النبي صلى الله عليه وسلم في سفر أصاب الناس فيها شدة، فقال عبد الله بن أبي لأصحابه: لا تنفقوا على من عند رسول الله حتى ينفضوا من حوله، وقال: {لئن رجعنا إلى المدينة ليخرجن الأعز منها الأذل} ، فأتيت النبي صلى الله عليه وسلم فأخبرته، فأرسل إلى عبد الله بن أبي، فسأله فاجتهد يمينه ما فعل، وقالوا: كذب زيد يا رسول الله، فوقع في نفسي مما قالوا شدة، حتى أنزل الله تصديقي في {إذا جاءك المنافقون} ، فدعاهم النبي صلى الله عليه وسلم ليستغفر لهم، فلووا رؤوسهم. وفي غزوة تبوك استنفرهم النبي صلى الله عليه وسلم كما استنفر غيرهم، فخرج بعضهم معه وبعضهم تخلفوا، وكان في الذين خرجوا معه من هم بقتله في الطريق، هموا بحل حزام ناقته ليقع في واد هناك، فجاءه الوحي، فأسر إلى حذيفة أسماءهم، ولذلك يقال: هو صاحب السر الذي لا يعلمه غيره، كما ثبت ذلك في الصحيح. ومع هذا ففي الظاهر تجري عليهم أحكام أهل الإيمان.
A8: 7 | B8: Yüksek (büyük ihtimal düzenlenmiş tekrar) | C8: MF-V07-S11-P007 | D8: IMN-S00-P152 | E8: 0.912 | F8: 0.774 | G8: 0.15 | H8: 0.03 | I8: S: V07P429–V07P459 T: V01P007–V01P359 | J8: شك مما يعلمه الإنسان من نفسه وإلا فهو يشك في تكميل العمل الذي خاف أن لا يكون كمله؛ فيخاف من نقصه ولا يشك في أصله. قال الخلال: وأخبرني محمد بن أبي هارون: أن حبيش بن سندي حدثهم في هذه المسألة. قال أبو عبد الله {قول النبي صلى الله عليه وسلم حين وقف على المقابر فقال: وإنا إن شاء الله بكم لاحقون} وقد نعيت إليه نفسه وعلم أنه صائر إلى الموت وفي قصة صاحب القبر " وعليه حييت وعليه مت وعليه تبعث إن شاء الله " وفي {قول النبي صلى الله عليه وسلم إني اختبأت دعوتي وهي نائلة إن شاء الله من لا يشرك بالله شيئا} {وفي مسألة الرجل النبي صلى الله عليه وسلم أحدنا يصبح جنبا يصوم؟ فقال: إني أفعل ذلك ثم أصوم فقال: إنك لست مثلنا أنت قد غفر الله لك ما تقدم من ذنبك وما تأخر فقال: والله إني لأرجو أن أكون أخشاكم لله} . وهذا كثير وأشباهه على اليقين. قال: ودخل عليه شيخ فسأله عن الإيمان فقال له: قول وعمل يزيد وينقص. فقال له: أقول: مؤمن إن شاء الله؟ قال: نعم. فقال له: إنهم يقولون لي إنك شاك؛ قال: بئس ما قالوا ثم خرج فقال: ردوه فقال: أليس يقولون: الإيمان قول وعمل يزيد وينقص؟ قال: نعم قال: هؤلاء يستثنون. قال له: كيف يا أبا عبد الله؟ قال: قل لهم: زعمتم أن الإيمان قول وعمل فالقول قد أتيتم به والعمل لم تأتوا به فهذا الاستثناء لهذا العمل قيل له يستثنى في الإيمان؟ قال: نعم أقول: أنا مؤمن إن شاء الله أستثني على اليقين لا على الشك؛ ثم قال: قال الله: {لتدخلن المسجد الحرام إن شاء الله آمنين} فقد أخبر الله تعالى أنهم داخلون المسجد الحرام. فقد بين أحمد في كلامه أنه يستثني مع تيقنه بما هو الآن موجود فيه يقوله بلسانه وقلبه لا يشك في ذلك ويستثني لكون العمل من الإيمان؛ وهو لا يتيقن أنه أكمله بل يشك في ذلك فنفى الشك وأثبت اليقين فيما يتيقنه من نفسه وأثبت الشك فيما لا يعلم وجوده وبين أن الاستثناء مستحب لهذا الثاني الذي لا يعلم هل أتى به أم لا وهو جائز أيضا لما يتيقنه فلو استثنى لنفس الموجود في قلبه جاز كقول النبي صلى الله عليه وسلم {والله إني لأرجو أن أكون أخشاكم لله} وهذا أمر موجود في الحال ليس بمستقبل وهو كونه أخشانا؛ فإنه لا يرجو أن يصير أخشانا لله؛ بل هو يرجو أن يكون حين هذا القول أخشانا لله. كما يرجو المؤمن إذا عمل عملا أن يكون الله تقبله منه ويخاف أن لا يكون تقبله منه. كما قال تعالى: {والذين يؤتون ما آتوا وقلوبهم وجلة أنهم إلى ربهم راجعون} وقال النبي صلى الله عليه وسلم {هو الرجل يصلي ويصوم ويتصدق ويخاف أن لا يقبل منه} والقبول هو أمر حاضر أو ماض وهو يرجوه ويخافه وذلك أن ما له عاقبة مستقبلة محمودة أو مذمومة والإنسان يجوز وجوده وعدمه. يقال: إنه يرجوه وإنه يخافه. فتعلق الرجاء والخوف بالحاضر والماضي لأن عاقبته المطلوبة والمكروهة مستقبلة. فهو يرجو أن يكون الله تقبل عمله فيثيبه عليه فيرحمه في المستقبل. ويخاف أن لا يكون تقبله فيحرم ثوابه. كما يخاف أن يكون الله قد سخط عليه في معصيته فيعاقبه عليها. وإذا كان الإنسان يسعى فيما يطلبه كتاجر أو بريد أرسله في حاجته يقضيها في بعض الأوقات فإذا مضى ذلك الوقت يقول أرجو أن يكون فلان قد قضى ذلك الأمر وقضاؤه ماض لكن ما يحصل لهذا من الفرح والسرور وغير ذلك من مقاصده مستقبل. ويقول الإنسان في الوقت الذي جرت عادة الحاج بدخولهم إلى مكة: أرجو أن يكونوا دخلوا ويقول في سرية بعثت إلى الكفار: نرجو أن يكون الله قد نصر المؤمنين وغنمهم ويقال في نيل مصر عند وقت ارتفاعه: نرجو أن يكون قد صعد النيل كما يقول الحاضر في مصر مثل هذا الوقت: نرجو أن يكون النيل في هذا العام نيلا مرتفعا ويقال لمن له أرض يحب أن تمطر إذا مطرت بعض النواحي أرجو أن يكون المطر عاما وأرجو أن تكون قد مطرت الأرض الفلانية وذلك لأن المرجو هو ما يفرح بوجوده ويسره فالمكروه ما يتألم بوجوده. وهذا يتعلق بالعلم والعلم بذلك مستقبل فإذا علم أن المسلمين انتصروا والحاج قد دخلوا أو المطر قد نزل فرح بذلك وحصل به مقاصد أخر له وإذا كان الأمر بخلاف ذلك لم يحصل ذلك المحبوب المطلوب فيقول: أرجو وأخاف لأن المحبوب والمكروه متعلق بالعلم بذلك وهو مستقبل وكذلك المطلوب بالإيمان من السعادة والنجاة هو أمر مستقبل فيستثنى في الحاضر بذلك لأن المطلوب به مستقبل ثم كل مطلوب مستقبل تعلق بمشيئة الله | K8: قال: ودخل عليه شيخ فسأله عن الإيمان، فقال له: قول وعمل، يزيد وينقص، فقال له: أقول: مؤمن إن شاء الله، قال: نعم. فقال له: إنهم يقولون لي: إنك شاك، قال: بئس ما قالوا، ثم خرج، فقال: ردوه، فقال: أليس يقولون: الإيمان قول وعمل يزيد وينقص؟ قال: نعم، قال: هؤلاء يستثنون. قال له: كيف يا أبا عبد الله؟ قال: قل لهم: زعمتم أن الإيمان قول وعمل، فالقول قد أتيتم به، والعمل لم تأتوا به، فهذا الاستثناء لهذا العمل، قيل له: يستثنى في الإيمان؟ قال: نعم، أقول: أنا مؤمن إن شاء الله، أستثنى على اليقين لا على الشك، ثم قال: قال الله: {لتدخلن المسجد الحرام إن شاء الله آمنين} ، فقد أخبر الله تعالى أنهم داخلون المسجد الحرام. فقد بين أحمد في كلامه أنه يستثنى مع تيقنه بما هو الآن موجود فيه، يقوله بلسانه وقلبه، لا يشك في ذلك، ويستثنى لكون العمل من الإيمان، وهو لا يتيقن أنه أكمله بل يشك في ذلك، فنفى الشك وأثبت اليقين، فيما يتيقنه من نفسه، وأثبت الشك فيما لا يعلم وجوده، وبين أن الاستثناء مستحب لهذا الثاني الذي لا يعلم هل أتى به أم لا، وهو جائز أيضا لما يتيقنه، فلو استثني لنفس الموجود في قلبه جاز، كقول النبي صلى الله عليه وسلم: " والله إني لأرجو أن أكون أخشاكم لله " وهذا أمر موجود في الحال ليس بمستقبل، وهو كونه أخشانا، فإنه لا يرجو أن يصير أخشانا لله، بل هو يرجو أن يكون حين هذا القول أخشانا لله. كما يرجو المؤمن إذا عمل عملا أن يكون الله تقبله منه ويخاف ألا يكون تقبله منه، كما قال تعالى {والذين يؤتون ما آتوا وقلوبهم وجلة أنهم إلى ربهم راجعون} [المؤمنون: 60] ، وقال النبي صلى الله عليه وسلم: " هو الرجل يصلي ويصوم ويتصدق ويخاف ألا يقبل منه " والقبول هو أمر حاضر أو ماض وهو يرجوه ويخافه، وذلك أن ماله عاقبة مستقبلة محمودة أو مذمومة، والإنسان يجوز وجوده وعدمه. يقال: إنه يرجوه وأنه يخافه. فتعلق الرجاء والخوف بالحاضر والماضى؛ لأن عاقبته المطلوبة والمكروهة مستقبلة. فهو يرجو أن يكون الله تقبل عمله فيثيبه عليه فيرحمه في المستقبل. ويخاف ألا يكون تقبله فيحرم ثوابه، كما يخاف أن يكون الله قد سخط عليه في معصيته فيعاقبه عليها. وإذا كان الإنسان يسعى فيما يطلبه كتاجر أو بريد أرسله في حاجته يقضيها في بعض الأوقات، فإذا مضى ذلك الوقت يقول: أرجو أن يكون فلان قد قضى ذلك الأمر، وقضاؤه ماض، لكن ما يحصل لهذا من الفرح والسرور وغير ذلك من مقاصده مستقبل، ويقول الإنسان في الوقت الذي جرت عادة الحاج بدخولهم إلى مكة: أرجو أن يكونوا دخلوا، ويقول في سرية بعثت إلى الكفار: نرجو أن يكون الله قد نصر المؤمنين وغنمهم، ويقال في نيل مصر عند وقت ارتفاعه: نرجو أن يكون قد صعد النيل، كما يقول الحاضر في مصر مثل هذا الوقت: نرجو أن يكون النيل في هذا العام نيلا مرتفعا، ويقال لمن له أرض يحب أن تمطر، إذا مطرت بعض النواحي: أرجو أن يكون المطر عاما، وأرجو أن تكون قد مطرت الأرض الفلانية، وذلك لأن المرجو هو ما يفرح بوجوده ويسره، فالمكروه ما يتألم بوجوده. وهذا يتعلق بالعلم، والعلم بذلك مستقبل، فإذا علم أن المسلمين انتصروا، والحاج قد دخلوا، أو المطر قد نزل، فرح بذلك وحصل به مقاصد أخر له، وإذا كان الأمر بخلاف ذلك لم يحصل ذلك المحبوب المطلوب، فيقول: أرجو وأخاف؛ لأن المحبوب والمكروه ما يتألم بوجوده. وهذا متعلق بالعلم بذلك وهو مستقبل، وكذلك المطلوب بالإيمان من السعادة والنجاة، هو أمر مستقبل، فيستثنى في الحاضر بذلك؛ لأن المطلوب به مستقبل، ثم كل مطلوب مستقبل، تعلق بمشيئة الله وإن جزم بوجوده؛ لأنه لا يكون مستقبل إلا بمشيئة الله. فقولنا: يكون هذا إن شاء الله، حق، فإنه لا يكون إلا إن شاء الله والشك واللفظ ليس فيه إلا التعليق، وليس من ضرورة التعليق الشك بل هذا بحسب علم المتكلم، فتارة يكون شاكا وتارة لا يكون شاكا، فلما كان الشك يصحبها كثيرا لعدم علم الإنسان بالعواقب، ظن الظان أن الشك داخل في معناها،
